Workbook

Sheet Summary
A4: SUMMARY OF EXPENSE CLAIM-BACK FOR ZOTT
A5: Period: | C5: 01/03/2026-31/03/2026
A7: No | B7: Platform | C7: Expense | D7: Claimback Details | E7: Total (exclude VAT) | F7: % VAT | G7: VAT Fee | H7: Grand total
A8: 1 | B8: TIKTOK | D8: Subsidy | E8: =-SUMIF(Defaut!G:G,"tiktok",Defaut!AF:AF) -> 124074.07 | F8: 0.1 | G8: =ROUND(E8*F8,0) -> 12407 | H8: =G8+E8 -> 136481.07
A9: 2 | B9: LAZADA | D9: Subsidy | E9: =-SUMIF(Defaut!G:G,"lazada",Defaut!AF:AF) -> 79629.639 | F9: 0.1 | G9: =ROUND(E9*F9,0) -> 7963 | H9: =G9+E9 -> 87592.639
A10: 3 | B10: SHOPEE | D10: Subsidy | E10: =-SUMIF(Defaut!G:G,"shopee_v2",Defaut!AF:AF) -> 26888712 | F10: 0.1 | G10: =ROUND(E10*F10,0) -> 2688871 | H10: =G10+E10 -> 29577583
A11: Phí vận hành gian hàng | E11: 35000000 | F11: 0.1 | G11: =ROUNDDOWN(E11*F11,0) -> 3500000 | H11: =G11+E11 -> 38500000
A12: Total value (exclude VAT) | E12: =SUBTOTAL(9,E8:E11) -> 62092416
A13: Thuế GTGT ( VAT) | E13: =SUBTOTAL(9,G8:G11) -> 6209241
A14: Total value (include VAT) | E14: =SUBTOTAL(9,H8:H11) -> 68301657

Sheet Defaut
S1: =SUM(S2:S1048576) -> 182490000 | U1: =SUM(U2:U1048576) -> 26135001 | Z1: =SUM(Z2:Z1048576) -> 1.53606e+08 | AB1: =SUM(AB2:AB1048576) -> 1.53606e+08 | AF1: =SUM(AF2:AF1048576) -> -27092416 | AG1: =SUM(AG2:AG1048576) -> -29801658
A2: Thời gian tạo | B2: Thời gian vận đơn được tạo | C2: Thời gian đóng gói hoàn thành | D2: Thời gian bàn giao | E2: Thời gian hoàn thành | F2: Thời gian đối soát | G2: Nền tảng | H2: Loại sản phẩm | I2: sku | J2: Tên sản phẩm | K2: Đơn vị xử lý đơn hàng (fulfill) | L2: Tiền tệ | M2: Trạng thái | N2: Mã đơn hàng Omisell | O2: Mã đơn hàng | P2: Trọng lượng | Q2: Thể tích | R2: Số lượng | S2: Số tiền hàng hoá | T2: Doanh thu | U2: Mã giảm giá từ người bán | V2: Giảm giá từ người bán | W2: Mã giảm giá từ nền tảng | X2: Giảm giá từ nền tảng | Y2: Giảm giá khác | Z2: NMV | AA2: Thuế GTGT | AB2: Revenue | AC2: Claim back | AD2: GAP | AE2: Vat | AF2: Subsidy (-VAT) | AG2: Subsidy (+VAT) | AH2: Note
A3: 2026-03-31 12:24:33 | B3: 2026-03-31 12:25:38 | C3: 2026-03-31 13:33:07 | D3: 2026-03-31 14:09:43 | E3: 2026-03-31 14:27:02 | F3: 2026-03-31 17:52:04 | G3: shopee_v2 | H3: physical | I3: MON055GH04VAN | J3: Váng sữa Zott Monte vị Vani nhập khẩu từ ĐỨC, bé 6 tháng tuổi trở lên (vỉ - 55g x 4 hũ) từ Sữa tươi, KHÔNG chất bảo quản | K3: merchant | L3: VND | M3: Giao hàng thành công | N3: ODVN2603318F7BC33D | O3: 260331JEART4VD | P3: 220 | R3: 2 | S3: 150000 | T3: 160000 | U3: 20000 | V3: 16000 | W3: 0 | X3: 44800 | Y3: 0 | Z3: 124000 | AA3: 8 | AB3: =Z3 -> 124000 | AC3: =IF(AB3-S3<0,"YES","NO") -> YES | AD3: =IF(AC3="NO",0,AB3-S3) -> -26000 | AE3: 0.08 | AF3: =AD3/(1+AE3) -> -24074.074 | AG3: =AF3*1.1 -> -26481.481
A4: 2026-03-31 10:20:42 | B4: 2026-03-31 10:26:08 | C4: 2026-03-31 10:28:56 | D4: 2026-03-31 11:05:47 | E4: 2026-03-31 11:13:59 | F4: 2026-03-31 11:14:48 | G4: shopee_v2 | H4: gift | I4: GIFT-YEMANDAM | J4: [HÀNG TẶNG KHÔNG BÁN] Yếm ăn dặm cho bé | K4: merchant | L4: VND | M4: Giao hàng thành công | N4: ODVN2603310C876F2B | O4: 260331J7DCVUWV | P4: 100 | Q4: 5x2x5 | R4: 1 | S4: 0 | T4: 0 | U4: 0 | V4: 0 | W4: 0 | X4: 0 | Y4: 0 | Z4: 0 | AA4: 8 | AB4: =Z4 -> 0 | AC4: =IF(AB4-S4<0,"YES","NO") -> NO | AD4: =IF(AC4="NO",0,AB4-S4) -> 0 | AE4: 0.08 | AF4: =AD4/(1+AE4) -> 0 | AG4: =AF4*1.1 -> 0
A5: 2026-03-31 10:20:42 | B5: 2026-03-31 10:26:08 | C5: 2026-03-31 10:28:56 | D5: 2026-03-31 11:05:47 | E5: 2026-03-31 11:13:59 | F5: 2026-03-31 11:14:48 | G5: shopee_v2 | H5: physical | I5: MON055GH04VAN | J5: Váng sữa Zott Monte vị Vani nhập khẩu từ ĐỨC, bé 6 tháng tuổi trở lên (vỉ - 55g x 4 hũ) từ Sữa tươi, KHÔNG chất bảo quản | K5: merchant | L5: VND | M5: Giao hàng thành công | N5: ODVN2603310C876F2B | O5: 260331J7DCVUWV | P5: 220 | R5: 4 | S5: 300000 | T5: 320000 | U5: 20000 | V5: 32000 | W5: 0 | X5: 65561 | Y5: 0 | Z5: 268000 | AA5: 8 | AB5: =Z5 -> 268000 | AC5: =IF(AB5-S5<0,"YES","NO") -> YES | AD5: =IF(AC5="NO",0,AB5-S5) -> -32000 | AE5: 0.08 | AF5: =AD5/(1+AE5) -> -29629.63 | AG5: =AF5*1.1 -> -32592.593
A6: 2026-03-30 22:48:52 | B6: 2026-03-30 22:54:18 | C6: 2026-03-31 09:10:06 | D6: 2026-03-31 09:25:25 | E6: 2026-03-31 10:33:32 | F6: 2026-03-31 10:47:26 | G6: shopee_v2 | H6: gift | I6: GIFT-YEMANDAM | J6: [HÀNG TẶNG KHÔNG BÁN] Yếm ăn dặm cho bé | K6: merchant | L6: VND | M6: Giao hàng thành công | N6: ODVN260330E5965C46 | O6: 260330H0R9XA8V | P6: 100 | Q6: 5x2x5 | R6: 1 | S6: 0 | T6: 0 | U6: 0 | V6: 0 | W6: 0 | X6: 0 | Y6: 0 | Z6: 0 | AA6: 8 | AB6: =Z6 -> 0 | AC6: =IF(AB6-S6<0,"YES","NO") -> NO | AD6: =IF(AC6="NO",0,AB6-S6) -> 0 | AE6: 0.08 | AF6: =AD6/(1+AE6) -> 0 | AG6: =AF6*1.1 -> 0
A7: 2026-03-30 22:48:52 | B7: 2026-03-30 22:54:18 | C7: 2026-03-31 09:10:06 | D7: 2026-03-31 09:25:25 | E7: 2026-03-31 10:33:32 | F7: 2026-03-31 10:47:26 | G7: shopee_v2 | H7: physical | I7: MON055GH04VAN | J7: Váng sữa Zott Monte vị Vani nhập khẩu từ ĐỨC, bé 6 tháng tuổi trở lên (vỉ - 55g x 4 hũ) từ Sữa tươi, KHÔNG chất bảo quản | K7: merchant | L7: VND | M7: Giao hàng thành công | N7: ODVN260330E5965C46 | O7: 260330H0R9XA8V | P7: 220 | R7: 6 | S7: 450000 | T7: 480000 | U7: 75000 | V7: 48000 | W7: 0 | X7: 135690 | Y7: 0 | Z7: 357000 | AA7: 8 | AB7: =Z7 -> 357000 | AC7: =IF(AB7-S7<0,"YES","NO") -> YES | AD7: =IF(AC7="NO",0,AB7-S7) -> -93000 | AE7: 0.08 | AF7: =AD7/(1+AE7) -> -86111.111 | AG7: =AF7*1.1 -> -94722.222
A8: 2026-03-30 18:45:59 | B8: 2026-03-30 22:51:13 | C8: 2026-03-31 09:04:31 | D8: 2026-03-31 10:26:21 | E8: 2026-03-31 10:44:55 | F8: 2026-03-31 21:54:20 | G8: shopee_v2 | H8: physical | I8: MON055GH04VAN | J8: Váng sữa Zott Monte vị Vani nhập khẩu từ ĐỨC, bé 6 tháng tuổi trở lên (vỉ - 55g x 4 hũ) từ Sữa tươi, KHÔNG chất bảo quản | K8: merchant | L8: VND | M8: Giao hàng thành công | N8: ODVN260330B4B89123 | O8: 260330GK601BKA | P8: 220 | R8: 2 | S8: 150000 | T8: 160000 | U8: 20000 | V8: 16000 | W8: 0 | X8: 44800 | Y8: 0 | Z8: 124000 | AA8: 8 | AB8: =Z8 -> 124000 | AC8: =IF(AB8-S8<0,"YES","NO") -> YES | AD8: =IF(AC8="NO",0,AB8-S8) -> -26000 | AE8: 0.08 | AF8: =AD8/(1+AE8) -> -24074.074 | AG8: =AF8*1.1 -> -26481.481
A9: 2026-03-30 11:52:51 | B9: 2026-03-30 12:45:40 | C9: 2026-03-30 13:39:09 | D9: 2026-03-30 15:17:21 | E9: 2026-03-30 16:25:41 | F9: 2026-03-31 09:35:35 | G9: shopee_v2 | H9: gift | I9: GIFT-YEMANDAM | J9: [HÀNG TẶNG KHÔNG BÁN] Yếm ăn dặm cho bé | K9: merchant | L9: VND | M9: Giao hàng thành công | N9: ODVN2603309EB51C35 | O9: 260330FV398093 | P9: 100 | Q9: 5x2x5 | R9: 1 | S9: 0 | T9: 0 | U9: 0 | V9: 0 | W9: 0 | X9: 0 | Y9: 0 | Z9: 0 | AA9: 8 | AB9: =Z9 -> 0 | AC9: =IF(AB9-S9<0,"YES","NO") -> NO | AD9: =IF(AC9="NO",0,AB9-S9) -> 0 | AE9: 0.08 | AF9: =AD9/(1+AE9) -> 0 | AG9: =AF9*1.1 -> 0
A10: 2026-03-30 11:52:51 | B10: 2026-03-30 12:45:40 | C10: 2026-03-30 13:39:09 | D10: 2026-03-30 15:17:21 | E10: 2026-03-30 16:25:41 | F10: 2026-03-31 09:35:35 | G10: shopee_v2 | H10: physical | I10: MNF055GC04VAN | J10: [Giao Hỏa Tốc] Phô mai tươi Montinis vị Vani nhập ĐỨC (vỉ - 55g x 4 hũ) | K10: merchant | L10: VND | M10: Giao hàng thành công | N10: ODVN2603309EB51C35 | O10: 260330FV398093 | P10: 220 | Q10: 10x10x15 | R10: 6 | S10: 354000 | T10: 420000 | U10: 75000 | V10: 37000.02 | W10: 0 | X10: 124999.98 | Y10: 0 | Z10: 307999.98 | AA10: 8 | AB10: =Z10 -> 307999.98 | AC10: =IF(AB10-S10<0,"YES","NO") -> YES | AD10: =IF(AC10="NO",0,AB10-S10) -> -46000.02 | AE10: 0.08 | AF10: =AD10/(1+AE10) -> -42592.611 | AG10: =AF10*1.1 -> -46851.872
A11: 2026-03-30 11:27:57 | B11: 2026-03-30 11:29:30 | C11: 2026-03-30 13:48:51 | D11: 2026-03-30 14:08:14 | E11: 2026-03-30 14:30:51 | F11: 2026-03-30 15:27:26 | G11: shopee_v2 | H11: gift | I11: GIFT-TAPDEGMS | J11: [HÀNG TẶNG KHÔNG BÁN] Tạp dề vào bếp xinh xắn Zott Gourmet Slices (màu ngẫu nhiên) | K11: merchant | L11: VND | M11: Giao hàng thành công | N11: ODVN26033069A3FF7C | O11: 260330FTPRGQR6 | P11: 20 | Q11: 5x2x5 | R11: 1 | S11: 0 | T11: 0 | U11: 0 | V11: 0 | W11: 0 | X11: 0 | Y11: 0 | Z11: 0 | AA11: 8 | AB11: =Z11 -> 0 | AC11: =IF(AB11-S11<0,"YES","NO") -> NO | AD11: =IF(AC11="NO",0,AB11-S11) -> 0 | AE11: 0.08 | AF11: =AD11/(1+AE11) -> 0 | AG11: =AF11*1.1 -> 0
A12: 2026-03-30 11:27:57 | B12: 2026-03-30 11:29:30 | C12: 2026-03-30 13:48:51 | D12: 2026-03-30 14:08:14 | E12: 2026-03-30 14:30:51 | F12: 2026-03-30 15:27:26 | G12: shopee_v2 | H12: physical | I12: GMS200GL12SDW | J12: Phô mai lát Zott Gourmet Slices SANDWICH nhập khẩu từ Đức, phù hợp cả gia đình (1 gói 200g – 12 lát), làm từ Sữa tươi giàu Canxi, Chất đạm | K12: merchant | L12: VND | M12: Giao hàng thành công | N12: ODVN26033069A3FF7C | O12: 260330FTPRGQR6 | P12: 200 | R12: 6 | S12: 432000 | T12: 480000 | U12: 75000 | V12: 48000 | W12: 0 | X12: 132120 | Y12: 0 | Z12: 357000 | AA12: 8 | AB12: =Z12 -> 357000 | AC12: =IF(AB12-S12<0,"YES","NO") -> YES | AD12: =IF(AC12="NO",0,AB12-S12) -> -75000 | AE12: 0.08 | AF12: =AD12/(1+AE12) -> -69444.444 | AG12: =AF12*1.1 -> -76388.889
A13: 2026-03-30 09:33:37 | B13: 2026-03-30 09:37:01 | C13: 2026-03-30 09:37:40 | D13: 2026-03-30 10:40:20 | E13: 2026-03-30 12:22:25 | F13: 2026-03-31 09:39:09 | G13: shopee_v2 | H13: gift | I13: GIFT-YEMANDAM | J13: [HÀNG TẶNG KHÔNG BÁN] Yếm ăn dặm cho bé | K13: merchant | L13: VND | M13: Giao hàng thành công | N13: ODVN260330FDE0969B | O13: 260330FMA99BAT | P13: 100 | Q13: 5x2x5 | R13: 1 | S13: 0 | T13: 0 | U13: 0 | V13: 0 | W13: 0 | X13: 0 | Y13: 0 | Z13: 0 | AA13: 8 | AB13: =Z13 -> 0 | AC13: =IF(AB13-S13<0,"YES","NO") -> NO | AD13: =IF(AC13="NO",0,AB13-S13) -> 0 | AE13: 0.08 | AF13: =AD13/(1+AE13) -> 0 | AG13: =AF13*1.1 -> 0
A14: 2026-03-30 09:33:37 | B14: 2026-03-30 09:37:01 | C14: 2026-03-30 09:37:40 | D14: 2026-03-30 10:40:20 | E14: 2026-03-30 12:22:25 | F14: 2026-03-31 09:39:09 | G14: shopee_v2 | H14: physical | I14: MON055GH04VAN | J14: Váng sữa Zott Monte vị Vani nhập khẩu từ ĐỨC, bé 6 tháng tuổi trở lên (vỉ - 55g x 4 hũ) từ Sữa tươi, KHÔNG chất bảo quản | K14: merchant | L14: VND | M14: Giao hàng thành công | N14: ODVN260330FDE0969B | O14: 260330FMA99BAT | P14: 220 | R14: 3 | S14: 225000 | T14: 240000 | U14: 35000.01 | V14: 24000 | W14: 0 | X14: 62150.01 | Y14: 0 | Z14: 180999.99 | AA14: 8 | AB14: =Z14 -> 180999.99 | AC14: =IF(AB14-S14<0,"YES","NO") -> YES | AD14: =IF(AC14="NO",0,AB14-S14) -> -44000.01 | AE14: 0.08 | AF14: =AD14/(1+AE14) -> -40740.75 | AG14: =AF14*1.1 -> -44814.825
A15: 2026-03-30 08:53:11 | B15: 2026-03-30 08:54:22 | C15: 2026-03-30 09:03:58 | D15: 2026-03-30 09:34:49 | E15: 2026-03-30 10:25:10 | F15: 2026-03-31 09:30:46 | G15: shopee_v2 | H15: physical | I15: MON055GH04CXP | J15: [Giao nhanh 2H] Váng sữa Zott Monte Canxi Plus nhập khẩu từ ĐỨC, bé 6 tháng tuổi trở lên (vỉ - 55g x 4 hũ) từ Sữa tươi, KHÔNG chất bảo quản | K15: merchant | L15: VND | M15: Giao hàng thành công | N15: ODVN260330CB3F03A4 | O15: 260330FJ1YQG72 | P15: 220 | R15: 2 | S15: 150000 | T15: 160000 | U15: 20000 | V15: 10000 | W15: 0 | X15: 33000 | Y15: 0 | Z15: 130000 | AA15: 8 | AB15: =Z15 -> 130000 | AC15: =IF(AB15-S15<0,"YES","NO") -> YES | AD15: =IF(AC15="NO",0,AB15-S15) -> -20000 | AE15: 0.08 | AF15: =AD15/(1+AE15) -> -18518.519 | AG15: =AF15*1.1 -> -20370.37
A16: 2026-03-30 07:46:47 | B16: 2026-03-30 07:52:02 | C16: 2026-03-30 08:54:41 | D16: 2026-03-30 09:12:14 | E16: 2026-03-30 09:58:51 | F16: 2026-03-31 20:36:04 | G16: shopee_v2 | H16: physical | I16: MON055GH04VAN | J16: Váng sữa Zott Monte vị Vani nhập khẩu từ ĐỨC, bé 6 tháng tuổi trở lên (vỉ - 55g x 4 hũ) từ Sữa tươi, KHÔNG chất bảo quản | K16: merchant | L16: VND | M16: Giao hàng thành công | N16: ODVN260330352D95CB | O16: 260330FEB87NYJ | P16: 220 | R16: 3 | S16: 225000 | T16: 240000 | U16: 35000.01 | V16: 24000 | W16: 0 | X16: 71199.99 | Y16: 0 | Z16: 180999.99 | AA16: 8 | AB16: =Z16 -> 180999.99 | AC16: =IF(AB16-S16<0,"YES","NO") -> YES | AD16: =IF(AC16="NO",0,AB16-S16) -> -44000.01 | AE16: 0.08 | AF16: =AD16/(1+AE16) -> -40740.75 | AG16: =AF16*1.1 -> -44814.825
A17: 2026-03-29 22:42:48 | B17: 2026-03-29 22:48:10 | C17: 2026-03-30 08:54:30 | D17: 2026-03-30 09:47:04 | E17: 2026-03-30 10:22:09 | F17: 2026-03-30 23:50:06 | G17: shopee_v2 | H17: physical | I17: MON055GH04VAN | J17: Váng sữa Zott Monte vị Vani nhập khẩu từ ĐỨC, bé 6 tháng tuổi trở lên (vỉ - 55g x 4 hũ) từ Sữa tươi, KHÔNG chất bảo quản | K17: merchant | L17: VND | M17: Giao hàng thành công | N17: ODVN260329DC12470A | O17: 260329EFXJ7M2E | P17: 220 | R17: 2 | S17: 150000 | T17: 160000 | U17: 20000 | V17: 16000 | W17: 0 | X17: 44800 | Y17: 0 | Z17: 124000 | AA17: 8 | AB17: =Z17 -> 124000 | AC17: =IF(AB17-S17<0,"YES","NO") -> YES | AD17: =IF(AC17="NO",0,AB17-S17) -> -26000 | AE17: 0.08 | AF17: =AD17/(1+AE17) -> -24074.074 | AG17: =AF17*1.1 -> -26481.481
A18: 2026-03-28 23:10:48 | B18: 2026-03-28 23:16:22 | C18: 2026-03-30 08:53:42 | D18: 2026-03-30 09:23:16 | E18: 2026-03-30 10:07:23 | F18: 2026-03-30 10:55:10 | G18: shopee_v2 | H18: physical | I18: MON055GH04VAN | J18: Váng sữa Zott Monte vị Vani nhập khẩu từ ĐỨC, bé 6 tháng tuổi trở lên (vỉ - 55g x 4 hũ) từ Sữa tươi, KHÔNG chất bảo quản | K18: merchant | L18: VND | M18: Giao hàng thành công | N18: ODVN26032888FDD9AA | O18: 260329C112YQ1G | P18: 220 | R18: 6 | S18: 450000 | T18: 480000 | U18: 75000 | V18: 48000 | W18: 0 | X18: 139260 | Y18: 0 | Z18: 357000 | AA18: 8 | AB18: =Z18 -> 357000 | AC18: =IF(AB18-S18<0,"YES","NO") -> YES | AD18: =IF(AC18="NO",0,AB18-S18) -> -93000 | AE18: 0.08 | AF18: =AD18/(1+AE18) -> -86111.111 | AG18: =AF18*1.1 -> -94722.222
A19: 2026-03-27 23:43:48 | B19: 2026-03-27 23:50:58 | C19: 2026-03-28 07:51:39 | D19: 2026-03-28 08:55:19 | E19: 2026-03-28 09:51:36 | F19: 2026-03-28 15:48:44 | G19: shopee_v2 | H19: physical | I19: MNS055GC04PLN | J19: [Giao Hoả Tốc] Sữa chua Montinis vị Nguyên bản nhập Đức (vỉ - 55g x 4 hũ) | K19: merchant | L19: VND | M19: Giao hàng thành công | N19: ODVN260327806DF183 | O19: 2603289JDNY4D7 | P19: 220 | Q19: 13x5x13 | R19: 3 | S19: 177000 | T19: 195000 | U19: 35000.01 | V19: 19500 | W19: 0 | X19: 63099.99 | Y19: 0 | Z19: 140499.99 | AA19: 8 | AB19: =Z19 -> 140499.99 | AC19: =IF(AB19-S19<0,"YES","NO") -> YES | AD19: =IF(AC19="NO",0,AB19-S19) -> -36500.01 | AE19: 0.08 | AF19: =AD19/(1+AE19) -> -33796.306 | AG19: =AF19*1.1 -> -37175.936
A20: 2026-03-27 21:46:44 | B20: 2026-03-27 22:03:40 | C20: 2026-03-28 10:24:19 | D20: 2026-03-28 10:34:55 | E20: 2026-03-28 11:40:02 | F20: 2026-03-28 15:12:15 | G20: shopee_v2 | H20: gift | I20: GIFT-TAPDEGMS | J20: [HÀNG TẶNG KHÔNG BÁN] Tạp dề vào bếp xinh xắn Zott Gourmet Slices (màu ngẫu nhiên) | K20: merchant | L20: VND | M20: Giao hàng thành công | N20: ODVN2603271FA1F4BD | O20: 2603279BVF6W9A | P20: 20 | Q20: 5x2x5 | R20: 1 | S20: 0 | T20: 0 | U20: 0 | V20: 0 | W20: 0 | X20: 0 | Y20: 0 | Z20: 0 | AA20: 8 | AB20: =Z20 -> 0 | AC20: =IF(AB20-S20<0,"YES","NO") -> NO | AD20: =IF(AC20="NO",0,AB20-S20) -> 0 | AE20: 0.08 | AF20: =AD20/(1+AE20) -> 0 | AG20: =AF20*1.1 -> 0
A21: 2026-03-27 21:46:44 | B21: 2026-03-27 22:03:40 | C21: 2026-03-28 10:24:19 | D21: 2026-03-28 10:34:55 | E21: 2026-03-28 11:40:02 | F21: 2026-03-28 15:12:15 | G21: shopee_v2 | H21: physical | I21: GMS200GL12SDW | J21: Phô mai lát Zott Gourmet Slices SANDWICH nhập khẩu từ Đức, phù hợp cả gia đình (1 gói 200g – 12 lát), làm từ Sữa tươi giàu Canxi, Chất đạm | K21: merchant | L21: VND | M21: Giao hàng thành công | N21: ODVN2603271FA1F4BD | O21: 2603279BVF6W9A | P21: 200 | R21: 6 | S21: 432000 | T21: 480000 | U21: 75000 | V21: 48000 | W21: 0 | X21: 135690 | Y21: 0 | Z21: 357000 | AA21: 8 | AB21: =Z21 -> 357000 | AC21: =IF(AB21-S21<0,"YES","NO") -> YES | AD21: =IF(AC21="NO",0,AB21-S21) -> -75000 | AE21: 0.08 | AF21: =AD21/(1+AE21) -> -69444.444 | AG21: =AF21*1.1 -> -76388.889
A22: 2026-03-27 21:35:46 | B22: 2026-03-27 21:48:42 | C22: 2026-03-28 08:39:47 | D22: 2026-03-28 09:18:58 | E22: 2026-03-28 10:02:12 | F22: 2026-03-28 21:58:01 | G22: shopee_v2 | H22: physical | I22: MON055GH04VAN | J22: Váng sữa Zott Monte vị Vani nhập khẩu từ ĐỨC, bé 6 tháng tuổi trở lên (vỉ - 55g x 4 hũ) từ Sữa tươi, KHÔNG chất bảo quản | K22: merchant | L22: VND | M22: Giao hàng thành công | N22: ODVN260327BCB906DF | O22: 2603279B8QU1RU | P22: 220 | R22: 6 | S22: 450000 | T22: 480000 | U22: 75000 | V22: 48000 | W22: 0 | X22: 164250 | Y22: 0 | Z22: 357000 | AA22: 8 | AB22: =Z22 -> 357000 | AC22: =IF(AB22-S22<0,"YES","NO") -> YES | AD22: =IF(AC22="NO",0,AB22-S22) -> -93000 | AE22: 0.08 | AF22: =AD22/(1+AE22) -> -86111.111 | AG22: =AF22*1.1 -> -94722.222
A23: 2026-03-27 14:54:36 | B23: 2026-03-27 14:57:39 | C23: 2026-03-27 15:32:31 | D23: 2026-03-27 15:50:41 | E23: 2026-03-27 16:31:53 | F23: 2026-03-30 17:43:25 | G23: shopee_v2 | H23: physical | I23: MON055GH04VAN | J23: Váng sữa Zott Monte vị Vani nhập khẩu từ ĐỨC, bé 6 tháng tuổi trở lên (vỉ - 55g x 4 hũ) từ Sữa tươi, KHÔNG chất bảo quản | K23: merchant | L23: VND | M23: Giao hàng thành công | N23: ODVN260327B119C04F | O23: 2603278MUGQYXR | P23: 220 | R23: 6 | S23: 450000 | T23: 480000 | U23: 75000 | V23: 48000 | W23: 0 | X23: 132120 | Y23: 0 | Z23: 357000 | AA23: 8 | AB23: =Z23 -> 357000 | AC23: =IF(AB23-S23<0,"YES","NO") -> YES | AD23: =IF(AC23="NO",0,AB23-S23) -> -93000 | AE23: 0.08 | AF23: =AD23/(1+AE23) -> -86111.111 | AG23: =AF23*1.1 -> -94722.222
A24: 2026-03-27 14:27:38 | B24: 2026-03-27 14:28:46 | C24: 2026-03-27 15:32:26 | D24: 2026-03-27 16:02:06 | E24: 2026-03-27 16:21:18 | F24: 2026-03-30 17:30:37 | G24: shopee_v2 | H24: gift | I24: GIFT-BOBONGRO | J24: [HÀNG TẶNG KHÔNG BÁN] Bộ đồ chơi bóng rổ đáng yêu (hình ngẫu nhiên) | K24: merchant | L24: VND | M24: Giao hàng thành công | N24: ODVN2603278A7E2EC8 | O24: 2603278KB9PRRF | P24: 20000 | Q24: 5x3x5 | R24: 1 | S24: 0 | T24: 0 | U24: 0 | V24: 0 | W24: 0 | X24: 0 | Y24: 0 | Z24: 0 | AA24: 8 | AB24: =Z24 -> 0 | AC24: =IF(AB24-S24<0,"YES","NO") -> NO | AD24: =IF(AC24="NO",0,AB24-S24) -> 0 | AE24: 0.08 | AF24: =AD24/(1+AE24) -> 0 | AG24: =AF24*1.1 -> 0
A25: 2026-03-27 14:27:38 | B25: 2026-03-27 14:28:46 | C25: 2026-03-27 15:32:26 | D25: 2026-03-27 16:02:06 | E25: 2026-03-27 16:21:18 | F25: 2026-03-30 17:30:37 | G25: shopee_v2 | H25: physical | I25: MNS055GC04MNG | J25: [Giao Hoả Tốc] Sữa chua Montinis vị Xoài nhập Đức (vỉ - 55g x 4 hũ) | K25: merchant | L25: VND | M25: Giao hàng thành công | N25: ODVN2603278A7E2EC8 | O25: 2603278KB9PRRF | P25: 220 | Q25: 13x5x13 | R25: 3 | S25: 177000 | T25: 195000 | U25: 35000.01 | V25: 19500 | W25: 0 | X25: 63099.99 | Y25: 0 | Z25: 140499.99 | AA25: 8 | AB25: =Z25 -> 140499.99 | AC25: =IF(AB25-S25<0,"YES","NO") -> YES | AD25: =IF(AC25="NO",0,AB25-S25) -> -36500.01 | AE25: 0.08 | AF25: =AD25/(1+AE25) -> -33796.306 | AG25: =AF25*1.1 -> -37175.936
A26: 2026-03-27 14:18:48 | B26: 2026-03-27 14:24:16 | C26: 2026-03-27 15:32:13 | D26: 2026-03-27 15:41:36 | E26: 2026-03-27 16:10:35 | F26: 2026-03-30 17:14:59 | G26: shopee_v2 | H26: physical | I26: MON055GH04VAN | J26: Váng sữa Zott Monte vị Vani nhập khẩu từ ĐỨC, bé 6 tháng tuổi trở lên (vỉ - 55g x 4 hũ) từ Sữa tươi, KHÔNG chất bảo quản | K26: merchant | L26: VND | M26: Giao hàng thành công | N26: ODVN2603272860DA52 | O26: 2603278JUG6HAD | P26: 220 | R26: 6 | S26: 450000 | T26: 480000 | U26: 79999.98 | V26: 48000 | W26: 0 | X26: 143359.98 | Y26: 0 | Z26: 352000.02 | AA26: 8 | AB26: =Z26 -> 352000.02 | AC26: =IF(AB26-S26<0,"YES","NO") -> YES | AD26: =IF(AC26="NO",0,AB26-S26) -> -97999.98 | AE26: 0.08 | AF26: =AD26/(1+AE26) -> -90740.722 | AG26: =AF26*1.1 -> -99814.794
A27: 2026-03-27 14:17:31 | B27: 2026-03-27 14:24:22 | C27: 2026-03-27 15:32:20 | D27: 2026-03-27 15:41:40 | E27: 2026-03-27 15:48:03 | F27: 2026-03-30 16:15:21 | G27: shopee_v2 | H27: physical | I27: MON055GH04VAN | J27: Váng sữa Zott Monte vị Vani nhập khẩu từ ĐỨC, bé 6 tháng tuổi trở lên (vỉ - 55g x 4 hũ) từ Sữa tươi, KHÔNG chất bảo quản | K27: merchant | L27: VND | M27: Giao hàng thành công | N27: ODVN2603271D5502AB | O27: 2603278JS6TBGW | P27: 220 | R27: 3 | S27: 225000 | T27: 240000 | U27: 35000.01 | V27: 24000 | W27: 0 | X27: 71199.99 | Y27: 0 | Z27: 180999.99 | AA27: 8 | AB27: =Z27 -> 180999.99 | AC27: =IF(AB27-S27<0,"YES","NO") -> YES | AD27: =IF(AC27="NO",0,AB27-S27) -> -44000.01 | AE27: 0.08 | AF27: =AD27/(1+AE27) -> -40740.75 | AG27: =AF27*1.1 -> -44814.825
A28: 2026-03-27 14:12:10 | B28: 2026-03-27 14:17:33 | C28: 2026-03-27 15:32:07 | D28: 2026-03-27 15:55:31 | E28: 2026-03-27 16:25:40 | F28: 2026-03-28 22:36:06 | G28: shopee_v2 | H28: gift | I28: GIFT-YEMANDAM | J28: [HÀNG TẶNG KHÔNG BÁN] Yếm ăn dặm cho bé | K28: merchant | L28: VND | M28: Giao hàng thành công | N28: ODVN260327D50C357E | O28: 2603278JFKP8A8 | P28: 100 | Q28: 5x2x5 | R28: 1 | S28: 0 | T28: 0 | U28: 0 | V28: 0 | W28: 0 | X28: 0 | Y28: 0 | Z28: 0 | AA28: 8 | AB28: =Z28 -> 0 | AC28: =IF(AB28-S28<0,"YES","NO") -> NO | AD28: =IF(AC28="NO",0,AB28-S28) -> 0 | AE28: 0.08 | AF28: =AD28/(1+AE28) -> 0 | AG28: =AF28*1.1 -> 0
A29: 2026-03-27 14:12:10 | B29: 2026-03-27 14:17:33 | C29: 2026-03-27 15:32:07 | D29: 2026-03-27 15:55:31 | E29: 2026-03-27 16:25:40 | F29: 2026-03-28 22:36:06 | G29: shopee_v2 | H29: physical | I29: MON055GH04CLA | J29: Váng sữa Zott Monte vị Classic nhập khẩu từ ĐỨC, bé 6 tháng tuổi trở lên (vỉ - 55g x 4 hũ) từ Sữa tươi, KHÔNG chất bảo quản | K29: merchant | L29: VND | M29: Giao hàng thành công | N29: ODVN260327D50C357E | O29: 2603278JFKP8A8 | P29: 220 | R29: 6 | S29: 450000 | T29: 480000 | U29: 75000 | V29: 49000.02 | W29: 0 | X29: 139080 | Y29: 0 | Z29: 355999.98 | AA29: 8 | AB29: =Z29 -> 355999.98 | AC29: =IF(AB29-S29<0,"YES","NO") -> YES | AD29: =IF(AC29="NO",0,AB29-S29) -> -94000.02 | AE29: 0.08 | AF29: =AD29/(1+AE29) -> -87037.056 | AG29: =AF29*1.1 -> -95740.761
A30: 2026-03-27 12:01:29 | B30: 2026-03-27 12:09:22 | C30: 2026-03-27 14:07:37 | D30: 2026-03-27 14:17:30 | E30: 2026-03-27 14:47:40 | F30: 2026-03-28 10:33:34 | G30: shopee_v2 | H30: gift | I30: GIFT-YEMANDAM | J30: [HÀNG TẶNG KHÔNG BÁN] Yếm ăn dặm cho bé | K30: merchant | L30: VND | M30: Giao hàng thành công | N30: ODVN260327733403EE | O30: 2603278B5XV70H | P30: 100 | Q30: 5x2x5 | R30: 1 | S30: 0 | T30: 0 | U30: 0 | V30: 0 | W30: 0 | X30: 0 | Y30: 0 | Z30: 0 | AA30: 8 | AB30: =Z30 -> 0 | AC30: =IF(AB30-S30<0,"YES","NO") -> NO | AD30: =IF(AC30="NO",0,AB30-S30) -> 0 | AE30: 0.08 | AF30: =AD30/(1+AE30) -> 0 | AG30: =AF30*1.1 -> 0
A31: 2026-03-27 12:01:29 | B31: 2026-03-27 12:09:22 | C31: 2026-03-27 14:07:37 | D31: 2026-03-27 14:17:30 | E31: 2026-03-27 14:47:40 | F31: 2026-03-28 10:33:34 | G31: shopee_v2 | H31: physical | I31: MON055GH04VAN | J31: Váng sữa Zott Monte vị Vani nhập khẩu từ ĐỨC, bé 6 tháng tuổi trở lên (vỉ - 55g x 4 hũ) từ Sữa tươi, KHÔNG chất bảo quản | K31: merchant | L31: VND | M31: Giao hàng thành công | N31: ODVN260327733403EE | O31: 2603278B5XV70H | P31: 220 | R31: 2 | S31: 150000 | T31: 160000 | U31: 0 | V31: 16000 | W31: 0 | X31: 28801 | Y31: 0 | Z31: 144000 | AA31: 8 | AB31: =Z31 -> 144000 | AC31: =IF(AB31-S31<0,"YES","NO") -> YES | AD31: =IF(AC31="NO",0,AB31-S31) -> -6000 | AE31: 0.08 | AF31: =AD31/(1+AE31) -> -5555.5556 | AG31: =AF31*1.1 -> -6111.1111
A32: 2026-03-27 11:57:22 | B32: 2026-03-27 12:04:17 | C32: 2026-03-27 13:55:17 | D32: 2026-03-27 14:32:33 | E32: 2026-03-27 15:33:46 | F32: 2026-03-30 16:52:17 | G32: shopee_v2 | H32: gift | I32: GIFT-YEMANDAM | J32: [HÀNG TẶNG KHÔNG BÁN] Yếm ăn dặm cho bé | K32: merchant | L32: VND | M32: Giao hàng thành công | N32: ODVN260327388966AD | O32: 2603278AXKBKVY | P32: 100 | Q32: 5x2x5 | R32: 1 | S32: 0 | T32: 0 | U32: 0 | V32: 0 | W32: 0 | X32: 0 | Y32: 0 | Z32: 0 | AA32: 8 | AB32: =Z32 -> 0 | AC32: =IF(AB32-S32<0,"YES","NO") -> NO | AD32: =IF(AC32="NO",0,AB32-S32) -> 0 | AE32: 0.08 | AF32: =AD32/(1+AE32) -> 0 | AG32: =AF32*1.1 -> 0
A33: 2026-03-27 11:57:22 | B33: 2026-03-27 12:04:17 | C33: 2026-03-27 13:55:17 | D33: 2026-03-27 14:32:33 | E33: 2026-03-27 15:33:46 | F33: 2026-03-30 16:52:17 | G33: shopee_v2 | H33: physical | I33: MON055GH04VAN | J33: Váng sữa Zott Monte vị Vani nhập khẩu từ ĐỨC, bé 6 tháng tuổi trở lên (vỉ - 55g x 4 hũ) từ Sữa tươi, KHÔNG chất bảo quản | K33: merchant | L33: VND | M33: Giao hàng thành công | N33: ODVN260327388966AD | O33: 2603278AXKBKVY | P33: 220 | R33: 6 | S33: 450000 | T33: 480000 | U33: 75000 | V33: 48000 | W33: 0 | X33: 132120 | Y33: 0 | Z33: 357000 | AA33: 8 | AB33: =Z33 -> 357000 | AC33: =IF(AB33-S33<0,"YES","NO") -> YES | AD33: =IF(AC33="NO",0,AB33-S33) -> -93000 | AE33: 0.08 | AF33: =AD33/(1+AE33) -> -86111.111 | AG33: =AF33*1.1 -> -94722.222
A34: 2026-03-27 11:37:20 | B34: 2026-03-27 11:52:35 | C34: 2026-03-27 13:43:18 | D34: 2026-03-27 14:07:38 | E34: 2026-03-27 15:00:14 | F34: 2026-03-28 09:49:57 | G34: shopee_v2 | H34: gift | I34: GIFT-BOBONGRO | J34: [HÀNG TẶNG KHÔNG BÁN] Bộ đồ chơi bóng rổ đáng yêu (hình ngẫu nhiên) | K34: merchant | L34: VND | M34: Giao hàng thành công | N34: ODVN260327780D5DBA | O34: 26032789TN70Y7 | P34: 20000 | Q34: 5x3x5 | R34: 1 | S34: 0 | T34: 0 | U34: 0 | V34: 0 | W34: 0 | X34: 0 | Y34: 0 | Z34: 0 | AA34: 8 | AB34: =Z34 -> 0 | AC34: =IF(AB34-S34<0,"YES","NO") -> NO | AD34: =IF(AC34="NO",0,AB34-S34) -> 0 | AE34: 0.08 | AF34: =AD34/(1+AE34) -> 0 | AG34: =AF34*1.1 -> 0
A35: 2026-03-27 11:37:20 | B35: 2026-03-27 11:52:35 | C35: 2026-03-27 13:43:18 | D35: 2026-03-27 14:07:38 | E35: 2026-03-27 15:00:14 | F35: 2026-03-28 09:49:57 | G35: shopee_v2 | H35: physical | I35: MNS055GC04MNG | J35: [Giao Hoả Tốc] Sữa chua Montinis vị Xoài nhập Đức (vỉ - 55g x 4 hũ) | K35: merchant | L35: VND | M35: Giao hàng thành công | N35: ODVN260327780D5DBA | O35: 26032789TN70Y7 | P35: 220 | Q35: 13x5x13 | R35: 1 | S35: 59000 | T35: 65000 | U35: 11666.67 | V35: 5000 | W35: 0 | X35: 21333.33 | Y35: 0 | Z35: 48333.33 | AA35: 8 | AB35: =Z35 -> 48333.33 | AC35: =IF(AB35-S35<0,"YES","NO") -> YES | AD35: =IF(AC35="NO",0,AB35-S35) -> -10666.67 | AE35: 0.08 | AF35: =AD35/(1+AE35) -> -9876.5463 | AG35: =AF35*1.1 -> -10864.201
A36: 2026-03-27 11:37:20 | B36: 2026-03-27 11:52:35 | C36: 2026-03-27 13:43:18 | D36: 2026-03-27 14:07:38 | E36: 2026-03-27 15:00:14 | F36: 2026-03-28 09:49:57 | G36: shopee_v2 | H36: physical | I36: MNS055GC04PLN | J36: [Giao Hoả Tốc] Sữa chua Montinis vị Nguyên bản nhập Đức (vỉ - 55g x 4 hũ) | K36: merchant | L36: VND | M36: Giao hàng thành công | N36: ODVN260327780D5DBA | O36: 26032789TN70Y7 | P36: 220 | Q36: 13x5x13 | R36: 1 | S36: 59000 | T36: 65000 | U36: 11666.67 | V36: 5000 | W36: 0 | X36: 21333.33 | Y36: 0 | Z36: 48333.33 | AA36: 8 | AB36: =Z36 -> 48333.33 | AC36: =IF(AB36-S36<0,"YES","NO") -> YES | AD36: =IF(AC36="NO",0,AB36-S36) -> -10666.67 | AE36: 0.08 | AF36: =AD36/(1+AE36) -> -9876.5463 | AG36: =AF36*1.1 -> -10864.201
A37: 2026-03-27 11:37:20 | B37: 2026-03-27 11:52:35 | C37: 2026-03-27 13:43:18 | D37: 2026-03-27 14:07:38 | E37: 2026-03-27 15:00:14 | F37: 2026-03-28 09:49:57 | G37: shopee_v2 | H37: physical | I37: MNS055GC04APL | J37: [Giao Hoả Tốc] Sữa chua Montinis vị Táo nhập Đức (vỉ - 55g x 4 hũ) | K37: merchant | L37: VND | M37: Giao hàng thành công | N37: ODVN260327780D5DBA | O37: 26032789TN70Y7 | P37: 220 | Q37: 13x5x13 | R37: 1 | S37: 59000 | T37: 65000 | U37: 11666.67 | V37: 5000 | W37: 0 | X37: 21333.33 | Y37: 0 | Z37: 48333.33 | AA37: 8 | AB37: =Z37 -> 48333.33 | AC37: =IF(AB37-S37<0,"YES","NO") -> YES | AD37: =IF(AC37="NO",0,AB37-S37) -> -10666.67 | AE37: 0.08 | AF37: =AD37/(1+AE37) -> -9876.5463 | AG37: =AF37*1.1 -> -10864.201
A38: 2026-03-27 11:35:24 | B38: 2026-03-27 11:52:43 | C38: 2026-03-27 13:40:43 | D38: 2026-03-27 14:23:24 | E38: 2026-03-27 15:08:25 | F38: 2026-03-28 09:36:06 | G38: shopee_v2 | H38: gift | I38: GIFT-YEMANDAM | J38: [HÀNG TẶNG KHÔNG BÁN] Yếm ăn dặm cho bé | K38: merchant | L38: VND | M38: Giao hàng thành công | N38: ODVN2603277A38A248 | O38: 26032789QAC0ET | P38: 100 | Q38: 5x2x5 | R38: 1 | S38: 0 | T38: 0 | U38: 0 | V38: 0 | W38: 0 | X38: 0 | Y38: 0 | Z38: 0 | AA38: 8 | AB38: =Z38 -> 0 | AC38: =IF(AB38-S38<0,"YES","NO") -> NO | AD38: =IF(AC38="NO",0,AB38-S38) -> 0 | AE38: 0.08 | AF38: =AD38/(1+AE38) -> 0 | AG38: =AF38*1.1 -> 0
A39: 2026-03-27 11:35:24 | B39: 2026-03-27 11:52:43 | C39: 2026-03-27 13:40:43 | D39: 2026-03-27 14:23:24 | E39: 2026-03-27 15:08:25 | F39: 2026-03-28 09:36:06 | G39: shopee_v2 | H39: physical | I39: MON055GH04VAN | J39: Váng sữa Zott Monte vị Vani nhập khẩu từ ĐỨC, bé 6 tháng tuổi trở lên (vỉ - 55g x 4 hũ) từ Sữa tươi, KHÔNG chất bảo quản | K39: merchant | L39: VND | M39: Giao hàng thành công | N39: ODVN2603277A38A248 | O39: 26032789QAC0ET | P39: 220 | R39: 2 | S39: 150000 | T39: 160000 | U39: 10628 | V39: 16000 | W39: 0 | X39: 37197 | Y39: 0 | Z39: 133372 | AA39: 8 | AB39: =Z39 -> 133372 | AC39: =IF(AB39-S39<0,"YES","NO") -> YES | AD39: =IF(AC39="NO",0,AB39-S39) -> -16628 | AE39: 0.08 | AF39: =AD39/(1+AE39) -> -15396.296 | AG39: =AF39*1.1 -> -16935.926
A40: 2026-03-27 11:35:24 | B40: 2026-03-27 11:52:43 | C40: 2026-03-27 13:40:43 | D40: 2026-03-27 14:23:24 | E40: 2026-03-27 15:08:25 | F40: 2026-03-28 09:36:06 | G40: shopee_v2 | H40: physical | I40: MNF055GC04STB | J40: [Giao Hỏa Tốc] Phô mai tươi Montinis vị Dâu nhập ĐỨC (vỉ - 55g x 4 hũ) | K40: merchant | L40: VND | M40: Giao hàng thành công | N40: ODVN2603277A38A248 | O40: 26032789QAC0ET | P40: 220 | Q40: 10x5x15 | R40: 1 | S40: 59000 | T40: 70000 | U40: 4686 | V40: 6500 | W40: 0 | X40: 16401.5 | Y40: 0 | Z40: 58814 | AA40: 8 | AB40: =Z40 -> 58814 | AC40: =IF(AB40-S40<0,"YES","NO") -> YES | AD40: =IF(AC40="NO",0,AB40-S40) -> -186 | AE40: 0.08 | AF40: =AD40/(1+AE40) -> -172.22222 | AG40: =AF40*1.1 -> -189.44444
...

Sheet Sheet2
A1: 260225K8FCCABB
A2: 260225K8FCCABB
A3: 260225K8AJV03Q
A4: 2602097U64GD5J
A5: 260201J2PCP562 | C5: MNF055GC04STB | E5: MNF055GC04VAN | H5: MON055GH04VAN

Sheet Check
A1: Mã đơn hàng | B1: NMV | C1: Shop | D1: Sàn trả | E1: CL | J1: 260305C91P1H8F | L1: MON055GH04CLA | N1: MON055GH04VAN
A2: 260224HT0R6DHC | B2: 357000 | C2: =VLOOKUP(A2,Defaut!O:O,2,0) -> #REF! | D2: =SUMIF([2]Sheet2!$C:$C,A2,[2]Sheet2!$M:$M) -> 357000 | E2: =D2-B2 -> 0 | J2: 260305B5VG29N9
A3: 260224HTBBPE5M | B3: 357000 | C3: =VLOOKUP(A3,Defaut!O:O,2,0) -> #REF! | D3: =SUMIF([2]Sheet2!$C:$C,A3,[2]Sheet2!$M:$M) -> 357000 | E3: =D3-B3 -> 0
A4: 260225M6TX49N2 | B4: 357000 | C4: =VLOOKUP(A4,Defaut!O:O,2,0) -> #REF! | D4: =SUMIF([2]Sheet2!$C:$C,A4,[2]Sheet2!$M:$M) -> 357000 | E4: =D4-B4 -> 0
A5: 260225M7FK0HYH | B5: 355999.98 | C5: =VLOOKUP(A5,Defaut!O:O,2,0) -> #REF! | D5: =SUMIF([2]Sheet2!$C:$C,A5,[2]Sheet2!$M:$M) -> 356000 | E5: =D5-B5 -> 0.02
A6: 260225MB8THV5Y | B6: 357000 | C6: =VLOOKUP(A6,Defaut!O:O,2,0) -> #REF! | D6: =SUMIF([2]Sheet2!$C:$C,A6,[2]Sheet2!$M:$M) -> 357000 | E6: =D6-B6 -> 0
A7: 260225N63PHKJU | B7: 180999.99 | C7: =VLOOKUP(A7,Defaut!O:O,2,0) -> #REF! | D7: =SUMIF([2]Sheet2!$C:$C,A7,[2]Sheet2!$M:$M) -> 181000 | E7: =D7-B7 -> 0.01
A8: 260226PDWCP2RF | B8: 271999.99 | C8: =VLOOKUP(A8,Defaut!O:O,2,0) -> #REF! | D8: =SUMIF([2]Sheet2!$C:$C,A8,[2]Sheet2!$M:$M) -> 272000 | E8: =D8-B8 -> 0.01
A9: 260226PJB693HT | B9: 124000 | C9: =VLOOKUP(A9,Defaut!O:O,2,0) -> #REF! | D9: =SUMIF([2]Sheet2!$C:$C,A9,[2]Sheet2!$M:$M) -> 124000 | E9: =D9-B9 -> 0
A10: 260226PKM7ESQK | B10: 180999.99 | C10: =VLOOKUP(A10,Defaut!O:O,2,0) -> #REF! | D10: =SUMIF([2]Sheet2!$C:$C,A10,[2]Sheet2!$M:$M) -> 181000 | E10: =D10-B10 -> 0.01
A11: 260226PV4MXSEJ | B11: 180999.99 | C11: =VLOOKUP(A11,Defaut!O:O,2,0) -> #REF! | D11: =SUMIF([2]Sheet2!$C:$C,A11,[2]Sheet2!$M:$M) -> 181000 | E11: =D11-B11 -> 0.01
A12: 260226Q23XKAYU | B12: 140499.99 | C12: =VLOOKUP(A12,Defaut!O:O,2,0) -> #REF! | D12: =SUMIF([2]Sheet2!$C:$C,A12,[2]Sheet2!$M:$M) -> 140500 | E12: =D12-B12 -> 0.01
A13: 260226Q2BPJ8UA | B13: 140499.99 | C13: =VLOOKUP(A13,Defaut!O:O,2,0) -> #REF! | D13: =SUMIF([2]Sheet2!$C:$C,A13,[2]Sheet2!$M:$M) -> 140500 | E13: =D13-B13 -> 0.01
A14: 260226Q2H6252U | B14: 124000 | C14: =VLOOKUP(A14,Defaut!O:O,2,0) -> #REF! | D14: =SUMIF([2]Sheet2!$C:$C,A14,[2]Sheet2!$M:$M) -> 124000 | E14: =D14-B14 -> 0
... A576: 260331JEART4VD | B576: 124000 | C576: =VLOOKUP(A576,Defaut!O:O,2,0) -> #REF! | D576: =SUMIF([2]Sheet2!$C:$C,A576,[2]Sheet2!$M:$M) -> 124000 | E576: =D576-B576 -> 0
A577: 523586247432246 | B577: 159999.99 | C577: =VLOOKUP(A577,Defaut!O:O,2,0) -> #REF! | D577: =VLOOKUP(A577,[1]Sheet2!$F:$G,2,0) -> 160000 | E577: =D577-B577 -> 0.01
A578: 525836549136523 | B578: 552000 | C578: =VLOOKUP(A578,Defaut!O:O,2,0) -> #REF! | D578: =VLOOKUP(A578,[1]Sheet2!$F:$G,2,0) -> 552000 | E578: =D578-B578 -> 0
A579: 525992773048327 | B579: 390000 | C579: =VLOOKUP(A579,Defaut!O:O,2,0) -> #REF! | D579: =VLOOKUP(A579,[1]Sheet2!$F:$G,2,0) -> 390000 | E579: =D579-B579 -> 0
A580: 582783452440463185 | B580: 65000 | C580: =VLOOKUP(A580,Defaut!O:O,2,0) -> #REF! | D580: =SUMIF('[3]Order details'!$A:$A,A580,'[3]Order details'!$G:$G) -> 65000 | E580: =D580-B580 -> 0
A581: 582820641108755993 | B581: 134000 | C581: =VLOOKUP(A581,Defaut!O:O,2,0) -> #REF! | D581: =SUMIF('[3]Order details'!$A:$A,A581,'[3]Order details'!$G:$G) -> 134000 | E581: =D581-B581 -> 0
A582: 582895129806079725 | B582: 260000 | C582: =VLOOKUP(A582,Defaut!O:O,2,0) -> #REF! | D582: =SUMIF('[3]Order details'!$A:$A,A582,'[3]Order details'!$G:$G) -> 260000 | E582: =D582-B582 -> 0
A583: 583006645176665976 | B583: 130000 | C583: =VLOOKUP(A583,Defaut!O:O,2,0) -> #REF! | D583: =SUMIF('[3]Order details'!$A:$A,A583,'[3]Order details'!$G:$G) -> 130000 | E583: =D583-B583 -> 0
A584: 583041928825111727 | B584: 384000 | C584: =VLOOKUP(A584,Defaut!O:O,2,0) -> #REF! | D584: =SUMIF('[3]Order details'!$A:$A,A584,'[3]Order details'!$G:$G) -> 384000 | E584: =D584-B584 -> 0
A585: 583087700030621209 | B585: 390000 | C585: =VLOOKUP(A585,Defaut!O:O,2,0) -> #REF! | D585: =SUMIF('[3]Order details'!$A:$A,A585,'[3]Order details'!$G:$G) -> 390000 | E585: =D585-B585 -> 0
